Thanks for clarifying. Yes, got it perfectly now.

Summary of Flow and Expectations

You're testing an integration test for the Ember backend (/secure/api/feedback), which internally calls Rant and Rave. You're simulating Rant and Rave with a Mock SLAL server (not the Ember mock server), and you don’t want to mock axios or secrets in test — you want the whole flow to be real.

Now your Ember backend logic handles:

Secrets missing → Throws error → Ember returns 500

Schema validation error in request body → Ember returns 400

Any error during axios post to Rant & Rave (mock SLAL) → Ember returns 500


So the mock SLAL route must simulate:

1. Happy path (returns 202 and valid JSON)


2. Missing API key in headers (returns 500)


3. Malformed body / schema violation (returns 400)


4. Simulated network / post failure / general error (returns 500 or throws)




---

Updated Plan for Mock SLAL POST /feedback Route

app.post('/secure/api/feedback', async (c) => {
  const authHeader = c.req.header('x-api-key');
  const body = await c.req.json();

  // Case 1: API Key is missing
  if (!authHeader) {
    return c.json({ error: 'API key missing' }, 500);
  }

  // Case 2: API Key is invalid
  if (authHeader !== 'mockApiKey') {
    return c.json({ error: 'Invalid API key' }, 500);
  }

  // Case 3: Malformed body (missing required fields)
  const hasRequiredFields =
    body &&
    typeof body.feedback === 'object' &&
    typeof body.feedback.score === 'string' &&
    typeof body.feedback.comment === 'string';

  if (!hasRequiredFields) {
    return c.json({ error: 'Malformed feedback body' }, 400);
  }

  // Case 4: Simulated general error (e.g., internal crash)
  if (body.feedback.comment.includes('crash')) {
    return c.json({ error: 'Unexpected server error' }, 500);
  }

  // Case 5: Happy path
  return c.json(
    {
      feedbackStatus: 'success',
      message: 'Feedback received for submission',
    },
    202
  );
});


---

How This Matches Ember Behavior

Any non-2xx from Rant & Rave (mock SLAL) will cause Ember to return 500 (as per your service logic).

Validation of incoming Ember /feedback request is done via schema (feedbackApiSchema) and results in 400 from Ember directly.

Secret not loaded in Ember → throws early → 500.



---

Bonus

In your Ember backend test (Pactum), you can:

Keep the test payload valid.

Change cookie (ck) to load different test user.

Manipulate headers or fields to trigger SLAL mock scenarios.

And ensure Ember responds accordingly with 202, 400, or 500.



---

Let me know when you're ready and I’ll help you:

Plug this into your mock SLAL Hono route.

Write the corresponding Pactum tests against the Ember /feedback route that exercise all 4-5 conditions.


Ready when you are.

Perfect! Based on your clarified flow, here's how we'll structure your Pactum integration tests for the Ember /feedback POST route. This assumes:

Ember backend talks to Rant & Rave, which is now mocked via Mock SLAL server.

Feedback is posted to Ember and then passed downstream to Rant & Rave.

We're testing Ember's behavior (status codes and body) based on different Mock SLAL responses.

In positive case, we spy and ensure Rant & Rave was called with correct body.



---

✅ 1. Valid Feedback Submission (Happy Path)

import { spec } from 'pactum';
import { describe, it, vi, expect, beforeEach, afterEach } from 'vitest';
import axios from 'axios';
import { apiTest } from '../../../fixture';

describe('POST /feedback', () => {
  const feedbackRequest = {
    comment: '#test Hello from Ember',
    starRating: 5,
    surveyCaptureType: 'EmberDashboard',
  };

  beforeEach(() => {
    vi.clearAllMocks();
    vi.spyOn(axios, 'post').mockResolvedValue({ status: 200, data: {} });
  });

  afterEach(() => {
    vi.restoreAllMocks();
  });

  apiTest('should submit valid feedback successfully', async ({ baseUrl }) => {
    await spec()
      .post(`${baseUrl}/secure/api/feedback`)
      .withCookies('ck', '970205143728')
      .withHeaders({
        'content-type': 'application/json',
        accept: 'application/json',
      })
      .withBody(feedbackRequest)
      .expectStatus(202)
      .expectJsonLike({ message: 'Feedback received for submission' });

    // Assert Rant & Rave was called with expected body (simplified)
    expect(axios.post).toHaveBeenCalledWith(
      expect.stringContaining('/mock-rant-rave-feedback'), // configured mock SLAL route
      expect.objectContaining({
        feedback: expect.any(String),
        comment: expect.any(String),
        source: 'Online',
      }),
      expect.objectContaining({
        headers: expect.objectContaining({
          'x-api-key': expect.any(String),
        }),
      })
    );
  });
});


---

❌ 2. Secrets Missing in Lambda Context

This case simulates when secrets (e.g. rantAndRave) are undefined.

apiTest('should fail when secrets are missing', async ({ baseUrl }) => {
  process.env.RANT_AND_RAVE_SECRET = ''; // or clear mock secrets if used

  await spec()
    .post(`${baseUrl}/secure/api/feedback`)
    .withCookies('ck', '970205143728')
    .withHeaders({ 'content-type': 'application/json' })
    .withBody({
      comment: '#test Hello from Ember',
      starRating: 5,
      surveyCaptureType: 'EmberDashboard',
    })
    .expectStatus(500)
    .expectBodyContains('Unable to submit feedback, missing secrets');
});


---

❌ 3. Rant & Rave API Key Invalid (simulate 403 from Mock SLAL)

apiTest('should fail when Rant & Rave API key is invalid', async ({ baseUrl }) => {
  vi.spyOn(axios, 'post').mockRejectedValue({ response: { status: 403, data: 'Forbidden' } });

  await spec()
    .post(`${baseUrl}/secure/api/feedback`)
    .withCookies('ck', '970205143728')
    .withHeaders({ 'content-type': 'application/json' })
    .withBody({
      comment: '#test Hello from Ember',
      starRating: 5,
      surveyCaptureType: 'EmberDashboard',
    })
    .expectStatus(500)
    .expectBodyContains('Internal Server Error');
});


---

❌ 4. Invalid Request Body (Missing comment)

This fails on Zod validation and returns 400.

apiTest('should fail with 400 for invalid feedback body', async ({ baseUrl }) => {
  await spec()
    .post(`${baseUrl}/secure/api/feedback`)
    .withCookies('ck', '970205143728')
    .withHeaders({ 'content-type': 'application/json' })
    .withBody({
      starRating: 5,
      surveyCaptureType: 'EmberDashboard',
    }) // no comment
    .expectStatus(400);
});


---

Let me know if you want to dynamically validate full mock payload using Zod schema as well, or test mobile platform conditions. Want me to add those too?

app.use('*', async (c, next) => {
  console.log(`[MOCK SLAL] ${c.req.method} ${c.req.url}`);
  return next();
});

const response = await fetch(rantAndRaveApiUrl, {
  method: 'POST',
  headers: {
    'Content-Type': 'application/json',
    'x-api-key': SECRETS.rantAndRave.rantAndRaveApiKey,
  },
  body: JSON.stringify(rrValidatedFeedback),
});


Great question!

1. Why as unknown as XiorError is used

You're using a plain object to manually mimic the structure of an actual XiorError instance. TypeScript doesn’t allow you to directly cast from a plain object to a class type like XiorError — because it's not technically an instance of that class. So the unknown intermediate cast bypasses that safety check:

const fakeError = { ... } as unknown as XiorError;

This tells TypeScript: “Trust me, this looks like a XiorError even if it's not a real instance.”


---

2. Why not use new XiorError(...) like AxiosError

With AxiosError, you can do:

new AxiosError(message, code, config, request, response);

But XiorError doesn't expose a similar public constructor — at least not one with all those arguments.

That’s why:

You can't instantiate it like AxiosError unless XiorError explicitly supports it.

You’d get a TypeScript error or runtime mismatch if the constructor doesn't accept those args.



---

3. What are your options?

Option A: Fake it (safely, only in test)

const xiorError = {
  name: 'XiorError',
  message: 'Xior error',
  response: {
    status: 400,
    data: { error_description: 'Invalid client credentials' },
  },
} as unknown as XiorError;

This is totally fine in tests.

Option B: Create a helper createFakeXiorError()

If you use it in multiple places:

function createFakeXiorError(message: string, status: number, description: string): XiorError {
  return {
    name: 'XiorError',
    message,
    response: {
      status,
      data: { error_description: description },
    },
  } as unknown as XiorError;
}

Let me know if you want to try checking the actual constructor signature of XiorError from the xior package, or if you're open to making a custom test utility.

Perfect — that image is super helpful!

You're absolutely right to challenge the previous assumption — and now that you’ve shown the source, here's the updated and confirmed answer:


---

Yes — you can use new XiorError(...) directly.

From your image, the XiorError class has a defined constructor:

constructor(message: string, request?: XiorRequestConfig, response?: XiorResponse<T>)

So you can construct it like this in your test:

import { XiorError } from 'xior';

const xiorError = new XiorError(
  'Xior error',
  undefined,
  {
    status: 400,
    data: {
      error_description: 'Invalid client credentials',
    },
  }
);

mockMoneyHubDataxior.get = vi.fn().mockRejectedValue(xiorError);

This works exactly like how you previously used AxiosError.


---

Summary

XiorError does have a constructor that accepts (message, request?, response?).

So you can construct a proper error object without faking it.

This is the cleanest and most type-safe way for your test.


Let me know if you want to extract this into a helper for reuse.

